Workbook

Sheet 汇总
A1: 序号 | B1: 年度 | C1: 月度 | D1: 账户 | E1: 收入 | F1: 支出 | G1: 结算金额 | H1: 备注
A2: 1 | B2: 2024 | C2: 11 | D2: MERCURY | E2: =SUM(Mercury2024!F2:F97) -> 6438.05 | F2: =SUM(Mercury2024!G2:G97) -> 4848.6 | G2: =E2-F2 -> 1589.45
A3: 2 | B3: 2024 | C3: 11 | D3: PayPal | E3: =SUM(PayPal2024!M2:M119) -> 1128.18 | F3: =SUM(PayPal2024!N2:N119) -> 518.94 | G3: =E3-F3 -> 609.24
A4: 3 | B4: 2024 | C4: 11 | D4: USDT | E4: =SUM(USDT2024!G2:G34) -> 2721.4654 | F4: =SUM(USDT2024!H2:H34) -> 4709.26 | G4: =E4-F4 -> -1987.7946
A5: 4 | B5: 2024 | C5: 11 | D5: WISE | E5: =SUM(Wise2024!N2:N5) -> 743.17 | F5: =SUM(Wise2024!O2:O5) -> 743 | G5: =E5-F5 -> 0.17
A6: 5 | B6: 2024 | C6: 11 | D6: TUTU | E6: =SUM(TUTU账目!E2:E8) -> 2336.08 | F6: =SUM(TUTU账目!G2:G8) -> 2738.76 | G6: =E6-F6 -> -402.68
A7: 6 | B7: 2024 | C7: 12 | D7: MERCURY | E7: =SUM(Mercury2024!F98:F106) -> 637.7 | F7: =SUM(Mercury2024!G98:G106) -> 906.77 | G7: =E7-F7 -> -269.07
A8: 7 | B8: 2024 | C8: 12 | D8: PayPal | E8: =SUM(PayPal2024!M120:M194) -> 833.34 | F8: =SUM(PayPal2024!N120:N194) -> 646.97 | G8: =E8-F8 -> 186.37
A9: 8 | B9: 2024 | C9: 12 | D9: USDT | G9: =E9-F9 -> 0
A10: 9 | B10: 2024 | C10: 12 | D10: WISE | E10: =SUM(Wise2024!N6:N25) -> 2049.86 | F10: =SUM(Wise2024!O6:O25) -> 453.11 | G10: =E10-F10 -> 1596.75
A11: 10 | B11: 2024 | C11: 12 | D11: TUTU | E11: =SUM(TUTU账目!E9) -> 0 | F11: =SUM(TUTU账目!G9) -> 409.14 | G11: =E11-F11 -> -409.14
A12: 11 | B12: 2025 | C12: 1 | D12: MERCURY | E12: =SUM(Mercury2025!F2:F7) -> 0 | F12: =SUM(Mercury2025!G2:G7) -> 1059.52 | G12: =E12-F12 -> -1059.52
A13: 12 | B13: 2025 | C13: 1 | D13: PayPal | E13: =SUM(PayPal2025!M2:M43) -> 316.52 | F13: =SUM(PayPal2025!N2:N43) -> 566.77 | G13: =E13-F13 -> -250.25
A14: 13 | B14: 2025 | C14: 1 | D14: USDT | E14: =SUM(USDT2025!H20:H33) -> 819.1751 | F14: =SUM(USDT2025!I20:I33) -> 1493.7251 | G14: =E14-F14 -> -674.55
A15: 14 | B15: 2025 | C15: 1 | D15: WISE | E15: =SUM(Wise2025!N2:N26) -> 2992.47 | F15: =SUM(Wise2025!O2:O26) -> 2000.77 | G15: =E15-F15 -> 991.7
A16: 15 | B16: 2025 | C16: 1 | D16: TUTU | E16: =SUM(TUTU账目!E10) -> 0 | F16: =SUM(TUTU账目!G10) -> 411.8 | G16: =E16-F16 -> -411.8
A17: 16 | B17: 2025 | C17: 1 | D17: 其它流水 | E17: =SUM(其它流水2025!J2) -> 0 | F17: =SUM(其它流水2025!L2)*-1 -> 375.56 | G17: =E17-F17 -> -375.56
A18: 17 | B18: 2025 | C18: 2 | D18: MERCURY | E18: =SUM(Mercury2025!F8:F16) -> 3325.31 | F18: =SUM(Mercury2025!G8:G16) -> 1430.77 | G18: =E18-F18 -> 1894.54
A19: 18 | B19: 2025 | C19: 2 | D19: PayPal | E19: =SUM(PayPal2025!M44:M80) -> 567.2 | F19: =SUM(PayPal2025!N44:N80) -> 604.21 | G19: =E19-F19 -> -37.01
A20: 19 | B20: 2025 | C20: 2 | D20: USDT | E20: =SUM(USDT2025!H34:H39) -> 882.0941 | F20: =SUM(USDT2025!I34:I35) -> 0 | G20: =E20-F20 -> 882.0941
A21: 20 | B21: 2025 | C21: 2 | D21: WISE | E21: =SUM(Wise2025!N27:N46) -> 1332.58 | F21: =SUM(Wise2025!O27:O46) -> 3979.77 | G21: =E21-F21 -> -2647.19
A22: 21 | B22: 2025 | C22: 2 | D22: TUTU | E22: =SUM(TUTU账目!E11) -> 0 | F22: =SUM(TUTU账目!G11) -> 409.9 | G22: =E22-F22 -> -409.9
A23: 22 | B23: 2025 | C23: 2 | D23: 其它流水 | E23: 0 | F23: 0 | G23: 0
A24: 23 | B24: 2025 | C24: 3 | D24: MERCURY | E24: =SUM(Mercury2025!F17:F41) -> 1672.78 | F24: =SUM(Mercury2025!G17:G41) -> 1328.56 | G24: =E24-F24 -> 344.22
A25: 24 | B25: 2025 | C25: 3 | D25: PayPal | E25: =SUM(PayPal2025!M81:M99) -> 78.47 | F25: =SUM(PayPal2025!N81:N99) -> 34.27 | G25: =E25-F25 -> 44.2
A26: 25 | B26: 2025 | C26: 3 | D26: USDT | E26: =SUM(USDT2025!H39:H59) -> 1573.9828 | F26: =SUM(USDT2025!I36) -> 0 | G26: =E26-F26 -> 1573.9828
A27: 26 | B27: 2025 | C27: 3 | D27: WISE | E27: 0 | F27: 0 | G27: =E27-F27 -> 0
A28: 27 | B28: 2025 | C28: 3 | D28: TUTU | E28: =SUM(TUTU账目!E12) -> 0 | F28: =SUM(TUTU账目!G12) -> 401.4 | G28: =E28-F28 -> -401.4
A29: 28 | B29: 2025 | C29: 3 | D29: 其它流水 | E29: 0 | F29: 0 | G29: =E29-F29 -> 0
A30: 29 | B30: 2025 | C30: 4 | D30: MERCURY | E30: =SUM(Mercury2025!F42:F58) -> 3106.11 | F30: =SUM(Mercury2025!G42:G58) -> 3860.84 | G30: =E30-F30 -> -754.73
A31: 30 | B31: 2025 | C31: 4 | D31: PayPal | E31: =SUM(PayPal2025!M100:M125) -> 128.82 | F31: =SUM(PayPal2025!N100:N125) -> 10.91 | G31: =E31-F31 -> 117.91
A32: 31 | B32: 2025 | C32: 4 | D32: USDT | E32: =SUM(USDT2025!H60:H84) -> 2330.4374 | F32: 0 | G32: =E32-F32 -> 2330.4374
A33: 32 | B33: 2025 | C33: 4 | D33: WISE | E33: =SUM(Wise2025!N47:N48) -> 1262.5 | F33: 0 | G33: =E33-F33 -> 1262.5
A34: 33 | B34: 2025 | C34: 4 | D34: TUTU | E34: =SUM(TUTU账目!E28) -> 0 | F34: =SUM(TUTU账目!G13) -> 400.12 | G34: =E34-F34 -> -400.12
A35: 34 | B35: 2025 | C35: 4 | D35: 支付宝 | E35: =SUM(支付宝!H2) -> 836 | F35: 0 | G35: =E35-F35 -> 836
A36: 35 | B36: 2025 | C36: 4 | D36: 其它流水 | E36: 0 | F36: 0 | G36: =E36-F36 -> 0
A37: 36 | B37: 2025 | C37: 5 | D37: MERCURY | E37: =SUM(Mercury2025!F59:F62) -> 864.9 | F37: =SUM(Mercury2025!G59:G62) -> 1945.5 | G37: =E37-F37 -> -1080.6
A38: 37 | B38: 2025 | C38: 5 | D38: PayPal | E38: =SUM(PayPal2025!M126:M155) -> 293.3 | F38: =SUM(PayPal2025!N126:N155) -> 20.82 | G38: =E38-F38 -> 272.48
A39: 38 | B39: 2025 | C39: 5 | D39: USDT | E39: =SUM(USDT2025!H85:H110) -> 2415.27 | F39: 0 | G39: =E39-F39 -> 2415.27
A40: 39 | B40: 2025 | C40: 5 | D40: WISE | E40: =SUM(Wise2025!N49:N52) -> 2090.55 | F40: 0 | G40: =E40-F40 -> 2090.55
...

Sheet Mercury2025
A1: Date (UTC) | B1: Y | C1: M | D1: Description | E1: Amount | F1: IN | G1: OUT | H1: Status | I1: Source Account | J1: Bank Description | K1: Reference | L1: Note | M1: Last Four Digits | N1: Name On Card | O1: Category | P1: GL Code | Q1: Timestamp | R1: Original Currency | S1: Check Number
A2: 01-30-2025 | B2: 2025 | C2: 1 | D2: Cloudflare | E2: -11.84 | F2: =IF(E2>0,E2*1,0) -> 0 | G2: =IF(E2<0,E2*-1,0) -> 11.84 | H2: Sent | I2: Mercury Checking xx9768 | J2: CLOUDFLARE | M2: 5180 | N2: XIANG JIAO | O2: Software | Q2: 01-30-2025 02:43:10 | R2: USD
A3: 01-22-2025 | B3: 2025 | C3: 1 | D3: Alibaba | E3: -10.8 | F3: =IF(E3>0,E3*1,0) -> 0 | G3: =IF(E3<0,E3*-1,0) -> 10.8 | H3: Sent | I3: Mercury Checking xx9768 | J3: Alibaba.com Europe Lim | M3: 5180 | N3: XIANG JIAO | O3: Retail | Q3: 01-22-2025 04:58:09 | R3: USD
A4: 01-18-2025 | B4: 2025 | C4: 1 | D4: Nodehatch | E4: -46.39 | F4: =IF(E4>0,E4*1,0) -> 0 | G4: =IF(E4<0,E4*-1,0) -> 46.39 | H4: Sent | I4: Mercury Checking xx9768 | J4: NODEHATCH | M4: 5180 | N4: XIANG JIAO | O4: Software | Q4: 01-18-2025 09:20:06 | R4: GBP
A5: 01-18-2025 | B5: 2025 | C5: 1 | D5: Intl. Transaction Fee | E5: -1.39 | F5: =IF(E5>0,E5*1,0) -> 0 | G5: =IF(E5<0,E5*-1,0) -> 1.39 | H5: Sent | I5: Mercury Checking xx9768 | O5: FinancialInstitutionsAndFees | Q5: 01-18-2025 09:20:06
A6: 45839 | B6: 2025 | C6: 1 | D6: O2 Network Limited | E6: -955.1 | F6: =IF(E6>0,E6*1,0) -> 0 | G6: =IF(E6<0,E6*-1,0) -> 955.1 | H6: Sent | I6: Mercury Checking xx9768 | J6: Send Money transaction initiated on Mercury | K6: From Stars Flying Inc via mercury.com | L6: Server Hardware Fees | Q6: 45839.65
A7: 45689 | B7: 2025 | C7: 1 | D7: OVHcloud | E7: -34 | F7: =IF(E7>0,E7*1,0) -> 0 | G7: =IF(E7<0,E7*-1,0) -> 34 | H7: Sent | I7: Mercury Checking xx9768 | J7: OVHcloud | M7: 4422 | N7: Ovise Case | O7: Software | Q7: 45689.086 | R7: USD
A8: 02-28-2025 | B8: 2025 | C8: 2 | D8: STRIPE | E8: 40.84 | F8: =IF(E8>0,E8*1,0) -> 40.84 | G8: =IF(E8<0,E8*-1,0) -> 0 | H8: Sent | I8: Mercury Checking xx9768 | J8: STRIPE; TRANSFER; STARS FLYING INC | Q8: 02-28-2025 13:39:30
A9: 02-27-2025 | B9: 2025 | C9: 2 | D9: STRIPE | E9: 24.55 | F9: =IF(E9>0,E9*1,0) -> 24.55 | G9: =IF(E9<0,E9*-1,0) -> 0 | H9: Sent | I9: Mercury Checking xx9768 | J9: STRIPE; TRANSFER; STARS FLYING INC | Q9: 02-27-2025 13:34:07
A10: 02-26-2025 | B10: 2025 | C10: 2 | D10: WISE US INC | E10: 1782.62 | F10: =IF(E10>0,E10*1,0) -> 1782.62 | G10: =IF(E10<0,E10*-1,0) -> 0 | H10: Sent | I10: Mercury Checking xx9768 | J10: WISE US INC; STARS FLYI; Stars Flying Inc | K10: From Stars Flying Inc Via WISE | Q10: 02-26-2025 23:00:40
A11: 02-26-2025 | B11: 2025 | C11: 2 | D11: GOOGLE | E11: 26.21 | F11: =IF(E11>0,E11*1,0) -> 26.21 | G11: =IF(E11<0,E11*-1,0) -> 0 | H11: Sent | I11: Mercury Checking xx9768 | J11: GOOGLE; ADWORDS:12; Stars Flying Inc | Q11: 02-26-2025 20:00:19
A12: 02-22-2025 | B12: 2025 | C12: 2 | D12: Alibaba | E12: -10.8 | F12: =IF(E12>0,E12*1,0) -> 0 | G12: =IF(E12<0,E12*-1,0) -> 10.8 | H12: Sent | I12: Mercury Checking xx9768 | J12: Alibaba.com Europe Lim | M12: 5180 | N12: XIANG JIAO | O12: Retail | Q12: 02-22-2025 04:28:04 | R12: USD
A13: 02-21-2025 | B13: 2025 | C13: 2 | D13: American Registry For In | E13: -50 | F13: =IF(E13>0,E13*1,0) -> 0 | G13: =IF(E13<0,E13*-1,0) -> 50 | H13: Sent | I13: Mercury Checking xx9768 | J13: ARIN | M13: 5180 | N13: XIANG JIAO | O13: Other | Q13: 02-21-2025 13:20:07 | R13: USD
A14: 45779 | B14: 2025 | C14: 2 | D14: O2 Network Limited | E14: -1335.97 | F14: =IF(E14>0,E14*1,0) -> 0 | G14: =IF(E14<0,E14*-1,0) -> 1335.97 | H14: Sent | I14: Mercury Checking xx9768 | J14: Send Money transaction initiated on Mercury | K14: From Stars Flying Inc via mercury.com | L14: Network fees | Q14: 45779.65
A15: 45749 | B15: 2025 | C15: 2 | D15: WISE US INC | E15: 1451.09 | F15: =IF(E15>0,E15*1,0) -> 1451.09 | G15: =IF(E15<0,E15*-1,0) -> 0 | H15: Sent | I15: Mercury Checking xx9768 | J15: WISE US INC; idc NESSBI; Stars Flying Inc | K15: From NESSBIT INC Via WISE | Q15: 45749.966
A16: 45690 | B16: 2025 | C16: 2 | D16: OVHcloud | E16: -34 | F16: =IF(E16>0,E16*1,0) -> 0 | G16: =IF(E16<0,E16*-1,0) -> 34 | H16: Sent | I16: Mercury Checking xx9768 | J16: OVHcloud | M16: 4422 | N16: Ovise Case | O16: Software | Q16: 45690.576 | R16: USD
A17: 3/31/2025 | B17: 2025 | C17: 3 | D17: O2 Network Limited | E17: -500 | F17: =IF(E17>0,E17*1,0) -> 0 | G17: =IF(E17<0,E17*-1,0) -> 500 | H17: Sent | I17: Mercury Checking xx9768 | J17: Send Money transaction initiated on Mercury | K17: From Stars Flying Inc via mercury.com, network fee. | Q17: 3/31/2025 14:35
A18: 3/31/2025 | B18: 2025 | C18: 3 | D18: STRIPE | E18: 50.95 | F18: =IF(E18>0,E18*1,0) -> 50.95 | G18: =IF(E18<0,E18*-1,0) -> 0 | H18: Sent | I18: Mercury Checking xx9768 | J18: STRIPE; TRANSFER; STARS FLYING INC | Q18: 3/31/2025 13:55
A19: 3/28/2025 | B19: 2025 | C19: 3 | D19: STRIPE | E19: 26.25 | F19: =IF(E19>0,E19*1,0) -> 26.25 | G19: =IF(E19<0,E19*-1,0) -> 0 | H19: Sent | I19: Mercury Checking xx9768 | J19: STRIPE; TRANSFER; STARS FLYING INC | Q19: 3/28/2025 12:42
A20: 3/26/2025 | B20: 2025 | C20: 3 | D20: STRIPE | E20: 320.8 | F20: =IF(E20>0,E20*1,0) -> 320.8 | G20: =IF(E20<0,E20*-1,0) -> 0 | H20: Sent | I20: Mercury Checking xx9768 | J20: STRIPE; TRANSFER; STARS FLYING INC | Q20: 3/26/2025 12:39
A21: 3/25/2025 | B21: 2025 | C21: 3 | D21: STRIPE | E21: 13.63 | F21: =IF(E21>0,E21*1,0) -> 13.63 | G21: =IF(E21<0,E21*-1,0) -> 0 | H21: Sent | I21: Mercury Checking xx9768 | J21: STRIPE; TRANSFER; STARS FLYING INC | Q21: 3/25/2025 12:58
A22: 3/24/2025 | B22: 2025 | C22: 3 | D22: STRIPE | E22: 133.53 | F22: =IF(E22>0,E22*1,0) -> 133.53 | G22: =IF(E22<0,E22*-1,0) -> 0 | H22: Sent | I22: Mercury Checking xx9768 | J22: STRIPE; TRANSFER; STARS FLYING INC | Q22: 3/24/2025 13:58
A23: 3/22/2025 | B23: 2025 | C23: 3 | D23: Alibaba | E23: -10.8 | F23: =IF(E23>0,E23*1,0) -> 0 | G23: =IF(E23<0,E23*-1,0) -> 10.8 | H23: Sent | I23: Mercury Checking xx9768 | J23: Alibaba.com Europe Lim | M23: 5180 | N23: XIANG JIAO | O23: Retail | Q23: 3/22/2025 8:39 | R23: USD
A24: 3/21/2025 | B24: 2025 | C24: 3 | D24: STRIPE | E24: 39.6 | F24: =IF(E24>0,E24*1,0) -> 39.6 | G24: =IF(E24<0,E24*-1,0) -> 0 | H24: Sent | I24: Mercury Checking xx9768 | J24: STRIPE; TRANSFER; STARS FLYING INC | Q24: 3/21/2025 13:02
A25: 3/20/2025 | B25: 2025 | C25: 3 | D25: STRIPE | E25: 214.59 | F25: =IF(E25>0,E25*1,0) -> 214.59 | G25: =IF(E25<0,E25*-1,0) -> 0 | H25: Sent | I25: Mercury Checking xx9768 | J25: STRIPE; TRANSFER; STARS FLYING INC | Q25: 3/20/2025 12:42
A26: 3/19/2025 | B26: 2025 | C26: 3 | D26: STRIPE | E26: 351.02 | F26: =IF(E26>0,E26*1,0) -> 351.02 | G26: =IF(E26<0,E26*-1,0) -> 0 | H26: Sent | I26: Mercury Checking xx9768 | J26: STRIPE; TRANSFER; STARS FLYING INC | Q26: 3/19/2025 12:59
A27: 3/18/2025 | B27: 2025 | C27: 3 | D27: STRIPE | E27: 72.81 | F27: =IF(E27>0,E27*1,0) -> 72.81 | G27: =IF(E27<0,E27*-1,0) -> 0 | H27: Sent | I27: Mercury Checking xx9768 | J27: STRIPE; TRANSFER; STARS FLYING INC | Q27: 3/18/2025 13:04
A28: 3/17/2025 | B28: 2025 | C28: 3 | D28: STRIPE | E28: 15.5 | F28: =IF(E28>0,E28*1,0) -> 15.5 | G28: =IF(E28<0,E28*-1,0) -> 0 | H28: Sent | I28: Mercury Checking xx9768 | J28: STRIPE; TRANSFER; STARS FLYING INC | Q28: 3/17/2025 13:14
A29: 3/14/2025 | B29: 2025 | C29: 3 | D29: STRIPE | E29: 55.48 | F29: =IF(E29>0,E29*1,0) -> 55.48 | G29: =IF(E29<0,E29*-1,0) -> 0 | H29: Sent | I29: Mercury Checking xx9768 | J29: STRIPE; TRANSFER; STARS FLYING INC | Q29: 3/14/2025 12:33
A30: 3/13/2025 | B30: 2025 | C30: 3 | D30: STRIPE | E30: 38.34 | F30: =IF(E30>0,E30*1,0) -> 38.34 | G30: =IF(E30<0,E30*-1,0) -> 0 | H30: Sent | I30: Mercury Checking xx9768 | J30: STRIPE; TRANSFER; STARS FLYING INC | Q30: 3/13/2025 13:13
A31: 45994 | B31: 2025 | C31: 3 | D31: STRIPE | E31: 20.06 | F31: =IF(E31>0,E31*1,0) -> 20.06 | G31: =IF(E31<0,E31*-1,0) -> 0 | H31: Sent | I31: Mercury Checking xx9768 | J31: STRIPE; TRANSFER; STARS FLYING INC | Q31: 45994.521
A32: 45964 | B32: 2025 | C32: 3 | D32: STRIPE | E32: 1.63 | F32: =IF(E32>0,E32*1,0) -> 1.63 | G32: =IF(E32<0,E32*-1,0) -> 0 | H32: Sent | I32: Mercury Checking xx9768 | J32: STRIPE; TRANSFER; STARS FLYING INC | Q32: 45964.531
A33: 45933 | B33: 2025 | C33: 3 | D33: STRIPE | E33: 13.97 | F33: =IF(E33>0,E33*1,0) -> 13.97 | G33: =IF(E33<0,E33*-1,0) -> 0 | H33: Sent | I33: Mercury Checking xx9768 | J33: STRIPE; TRANSFER; STARS FLYING INC | Q33: 45933.787
A34: 45841 | B34: 2025 | C34: 3 | D34: STRIPE | E34: 60.96 | F34: =IF(E34>0,E34*1,0) -> 60.96 | G34: =IF(E34<0,E34*-1,0) -> 0 | H34: Sent | I34: Mercury Checking xx9768 | J34: STRIPE; TRANSFER; STARS FLYING INC | Q34: 45841.667
A35: 45811 | B35: 2025 | C35: 3 | D35: O2 Network Limited | E35: -380 | F35: =IF(E35>0,E35*1,0) -> 0 | G35: =IF(E35<0,E35*-1,0) -> 380 | H35: Sent | I35: Mercury Checking xx9768 | J35: Send Money transaction initiated on Mercury | K35: From Stars Flying Inc via mercury.com, network fee. | Q35: 45811.649
A36: 45811 | B36: 2025 | C36: 3 | D36: STRIPE | E36: 83.96 | F36: =IF(E36>0,E36*1,0) -> 83.96 | G36: =IF(E36<0,E36*-1,0) -> 0 | H36: Sent | I36: Mercury Checking xx9768 | J36: STRIPE; TRANSFER; STARS FLYING INC | Q36: 45811.583
A37: 45780 | B37: 2025 | C37: 3 | D37: STRIPE | E37: 99.47 | F37: =IF(E37>0,E37*1,0) -> 99.47 | G37: =IF(E37<0,E37*-1,0) -> 0 | H37: Sent | I37: Mercury Checking xx9768 | J37: STRIPE; TRANSFER; STARS FLYING INC | Q37: 45780.608
A38: 45750 | B38: 2025 | C38: 3 | D38: O2 Network Limited | E38: -403.76 | F38: =IF(E38>0,E38*1,0) -> 0 | G38: =IF(E38<0,E38*-1,0) -> 403.76 | H38: Sent | I38: Mercury Checking xx9768 | J38: Send Money transaction initiated on Mercury | K38: From Stars Flying Inc via mercury.com. Network fee. | Q38: 45750.649
A39: 45750 | B39: 2025 | C39: 3 | D39: STRIPE | E39: 53.58 | F39: =IF(E39>0,E39*1,0) -> 53.58 | G39: =IF(E39<0,E39*-1,0) -> 0 | H39: Sent | I39: Mercury Checking xx9768 | J39: STRIPE; TRANSFER; STARS FLYING INC | Q39: 45750.631
A40: 45719 | B40: 2025 | C40: 3 | D40: STRIPE | E40: 6.65 | F40: =IF(E40>0,E40*1,0) -> 6.65 | G40: =IF(E40<0,E40*-1,0) -> 0 | H40: Sent | I40: Mercury Checking xx9768 | J40: STRIPE; TRANSFER; STARS FLYING INC | Q40: 45719.583
...

Sheet PayPal2025
A1: Date | B1: Y | C1: M | D1: Time | E1: TimeZone | F1: Name | G1: Type | H1: Status | I1: Currency | J1: Gross | K1: Fee | L1: Net | M1: IN | N1: OUT | O1: Transaction ID | P1: Balance
A2: 45658 | B2: 2025 | C2: 1 | D2: 0.1406713 | E2: PST | F2: Lustig Jessy | G2: 网站付款 | H2: 已完成 | I2: USD | J2: 20.25 | K2: -1.5 | L2: 18.75 | M2: =IF(L2>0,L2,0) -> 18.75 | N2: =IF(L2<0,L2,0)*-1 -> 0 | O2: 5NN567791J961805J | P2: 824.79
A3: 45658 | B3: 2025 | C3: 1 | D3: 0.24979167 | E3: PST | F3: 明杰 盛 | G3: 定期付款 | H3: 已完成 | I3: USD | J3: 20.25 | K3: -1.5 | L3: 18.75 | M3: =IF(L3>0,L3,0) -> 18.75 | N3: =IF(L3<0,L3,0)*-1 -> 0 | O3: 7GU22998TH945710T | P3: 843.54
A4: 45658 | B4: 2025 | C4: 1 | D4: 0.42976852 | E4: PST | F4: Shengche Lin | G4: 网站付款 | H4: 已完成 | I4: USD | J4: 20.25 | K4: -1.2 | L4: 19.05 | M4: =IF(L4>0,L4,0) -> 19.05 | N4: =IF(L4<0,L4,0)*-1 -> 0 | O4: 0D416666A9629534V | P4: 862.59
A5: 45658 | B5: 2025 | C5: 1 | D5: 0.61780093 | E5: PST | F5: shu sheng | G5: 网站付款 | H5: 已完成 | I5: USD | J5: 20.25 | K5: -1.5 | L5: 18.75 | M5: =IF(L5>0,L5,0) -> 18.75 | N5: =IF(L5<0,L5,0)*-1 -> 0 | O5: 6DN09443A2395982X | P5: 881.34
A6: 45661 | B6: 2025 | C6: 1 | D6: 0.15452546 | E6: PST | F6: Coa Pac | G6: 定期付款 | H6: 已完成 | I6: USD | J6: 11.99 | K6: -0.91 | L6: 11.08 | M6: =IF(L6>0,L6,0) -> 11.08 | N6: =IF(L6<0,L6,0)*-1 -> 0 | O6: 6RY063221M9508732 | P6: 892.42
A7: 45661 | B7: 2025 | C7: 1 | D7: 0.20732639 | E7: PST | F7: zhuang wang | G7: 定期付款 | H7: 已完成 | I7: USD | J7: 23.99 | K7: -1.33 | L7: 22.66 | M7: =IF(L7>0,L7,0) -> 22.66 | N7: =IF(L7<0,L7,0)*-1 -> 0 | O7: 2JC26621MR463905F | P7: 915.08
A8: 45662 | B8: 2025 | C8: 1 | D8: 0.14756944 | E8: PST | F8: Ryan Kim | G8: 定期付款 | H8: 已完成 | I8: USD | J8: 4.99 | K8: -0.66 | L8: 4.33 | M8: =IF(L8>0,L8,0) -> 4.33 | N8: =IF(L8<0,L8,0)*-1 -> 0 | O8: 0S46609254646530E | P8: 919.41
A9: 45662 | B9: 2025 | C9: 1 | D9: 0.37520833 | E9: PST | G9: 用户发起的收款 | H9: 已完成 | I9: USD | J9: -500 | K9: 0 | L9: -500 | M9: =IF(L9>0,L9,0) -> 0 | N9: =IF(L9<0,L9,0)*-1 -> 500 | O9: 11918658BA516522P | P9: 419.41
A10: 45663 | B10: 2025 | C10: 1 | D10: 0.13030093 | E10: PST | F10: 宇 陈 | G10: 定期付款 | H10: 已完成 | I10: USD | J10: 4.99 | K10: -0.74 | L10: 4.25 | M10: =IF(L10>0,L10,0) -> 4.25 | N10: =IF(L10<0,L10,0)*-1 -> 0 | O10: 7FC79867RW773361X | P10: 423.66
A11: 45663 | B11: 2025 | C11: 1 | D11: 0.14759259 | E11: PST | F11: JIANWEN PENG | G11: 定期付款 | H11: 已完成 | I11: USD | J11: 2.99 | K11: -0.64 | L11: 2.35 | M11: =IF(L11>0,L11,0) -> 2.35 | N11: =IF(L11<0,L11,0)*-1 -> 0 | O11: 47W20796YF363925D | P11: 426.01
A12: 45663 | B12: 2025 | C12: 1 | D12: 0.33469907 | E12: PST | F12: PayPal | G12: 冻结余额以调查争议 | H12: 待处理 | I12: USD | J12: -2.35 | K12: 0 | L12: -2.35 | M12: =IF(L12>0,L12,0) -> 0 | N12: =IF(L12<0,L12,0)*-1 -> 2.35 | O12: 4R026402SJ4863157 | P12: 423.66
A13: 45663 | B13: 2025 | C13: 1 | D13: 0.34497685 | E13: PST | F13: PayPal | G13: 退单 | H13: 已完成 | I13: USD | J13: -2.99 | K13: 0 | L13: -2.99 | M13: =IF(L13>0,L13,0) -> 0 | N13: =IF(L13<0,L13,0)*-1 -> 2.99 | O13: 01F45106WR374003K | P13: 420.67
A14: 45663 | B14: 2025 | C14: 1 | D14: 0.34497685 | E14: PST | F14: PayPal | G14: 取消冻结以解决争议 | H14: 被拒绝 | I14: USD | J14: 2.35 | K14: 0 | L14: 2.35 | M14: =IF(L14>0,L14,0) -> 2.35 | N14: =IF(L14<0,L14,0)*-1 -> 0 | O14: 4R026402SJ4863157 | P14: 423.02
A15: 45663 | B15: 2025 | C15: 1 | D15: 0.71525463 | E15: PST | F15: PayPal | G15: 冻结余额以调查争议 | H15: 待处理 | I15: USD | J15: -4.25 | K15: 0 | L15: -4.25 | M15: =IF(L15>0,L15,0) -> 0 | N15: =IF(L15<0,L15,0)*-1 -> 4.25 | O15: 73509792698077259 | P15: 418.77
A16: 45663 | B16: 2025 | C16: 1 | D16: 0.85825231 | E16: PST | F16: chong yang | G16: 定期付款 | H16: 已完成 | I16: USD | J16: 1.09 | K16: -0.53 | L16: 0.56 | M16: =IF(L16>0,L16,0) -> 0.56 | N16: =IF(L16<0,L16,0)*-1 -> 0 | O16: 0A845910FC111801M | P16: 419.33
A17: 45663 | B17: 2025 | C17: 1 | D17: 0.86299769 | E17: PST | F17: PayPal | G17: 退单 | H17: 已完成 | I17: USD | J17: -4.99 | K17: 0 | L17: -4.99 | M17: =IF(L17>0,L17,0) -> 0 | N17: =IF(L17<0,L17,0)*-1 -> 4.99 | O17: 5U414574VP812392T | P17: 414.34
A18: 45663 | B18: 2025 | C18: 1 | D18: 0.86299769 | E18: PST | F18: PayPal | G18: 取消冻结以解决争议 | H18: 被拒绝 | I18: USD | J18: 4.25 | K18: 0 | L18: 4.25 | M18: =IF(L18>0,L18,0) -> 4.25 | N18: =IF(L18<0,L18,0)*-1 -> 0 | O18: 73509792698077259 | P18: 418.59
A19: 45664 | B19: 2025 | C19: 1 | D19: 0.85465278 | E19: PST | F19: Ryan Kim | G19: 付款退款 | H19: 已完成 | I19: USD | J19: -4.99 | K19: 0.17 | L19: -4.82 | M19: =IF(L19>0,L19,0) -> 0 | N19: =IF(L19<0,L19,0)*-1 -> 4.82 | O19: 5NK3273144414422F | P19: 413.77
A20: 45665 | B20: 2025 | C20: 1 | D20: 0.96483796 | E20: PST | F20: 枝光 真優 | G20: 网站付款 | H20: 已完成 | I20: USD | J20: 2.49 | K20: -0.61 | L20: 1.88 | M20: =IF(L20>0,L20,0) -> 1.88 | N20: =IF(L20<0,L20,0)*-1 -> 0 | O20: 2NF44876692074450 | P20: 415.65
A21: 45665 | B21: 2025 | C21: 1 | D21: 0.99644676 | E21: PST | F21: 枝光 真優 | G21: 付款退款 | H21: 已完成 | I21: USD | J21: -2.49 | K21: 0.12 | L21: -2.37 | M21: =IF(L21>0,L21,0) -> 0 | N21: =IF(L21<0,L21,0)*-1 -> 2.37 | O21: 4T260464W89374408 | P21: 413.28
... A57: 45696 | B57: 2025 | C57: 2 | D57: 0.9265625 | E57: PST | F57: Ryan Kim | G57: 付款退款 | H57: 已完成 | I57: USD | J57: -4.99 | K57: 0.17 | L57: -4.82 | M57: =IF(L57>0,L57,0) -> 0 | N57: =IF(L57<0,L57,0)*-1 -> 4.82 | O57: 7LY15274FN919084H | P57: 784.56
A58: 45696 | B58: 2025 | C58: 2 | D58: 0.96342593 | E58: PST | G58: 争议费 | H58: 已完成 | I58: USD | J58: -15 | K58: 0 | L58: -15 | M58: =IF(L58>0,L58,0) -> 0 | N58: =IF(L58<0,L58,0)*-1 -> 15 | O58: 9CA59849X66857532 | P58: 769.56
A59: 45696 | B59: 2025 | C59: 2 | D59: 0.9634375 | E59: PST | F59: PayPal | G59: 退单 | H59: 已完成 | I59: USD | J59: -35.99 | K59: 0 | L59: -35.99 | M59: =IF(L59>0,L59,0) -> 0 | N59: =IF(L59<0,L59,0)*-1 -> 35.99 | O59: 79K953502H018482H | P59: 733.57
A60: 45696 | B60: 2025 | C60: 2 | D60: 0.9634375 | E60: PST | F60: PayPal | G60: 取消冻结以解决争议 | H60: 被拒绝 | I60: USD | J60: 34.24 | K60: 0 | L60: 34.24 | M60: =IF(L60>0,L60,0) -> 34.24 | N60: =IF(L60<0,L60,0)*-1 -> 0 | O60: 5KT7877346451643R | P60: 767.81
A61: 45698 | B61: 2025 | C61: 2 | D61: 0.38609954 | E61: PST | F61: 程 常 | G61: 定期付款 | H61: 已完成 | I61: USD | J61: 20.25 | K61: -1.5 | L61: 18.75 | M61: =IF(L61>0,L61,0) -> 18.75 | N61: =IF(L61<0,L61,0)*-1 -> 0 | O61: 05H76178LW7354158 | P61: 786.56
A62: 45698 | B62: 2025 | C62: 2 | D62: 0.9737037 | E62: PST | F62: YIFAN SHI | G62: 网站付款 | H62: 已完成 | I62: USD | J62: 23.99 | K62: -1.69 | L62: 22.3 | M62: =IF(L62>0,L62,0) -> 22.3 | N62: =IF(L62<0,L62,0)*-1 -> 0 | O62: 87875665PT1232259 | P62: 808.86
A63: 45699 | B63: 2025 | C63: 2 | D63: 0.43604167 | E63: PST | G63: 用户发起的收款 | H63: 已完成 | I63: USD | J63: -500 | K63: 0 | L63: -500 | M63: =IF(L63>0,L63,0) -> 0 | N63: =IF(L63<0,L63,0)*-1 -> 500 | O63: 76Y52904PY775982W | P63: 308.86
A64: 45700 | B64: 2025 | C64: 2 | D64: 0.88635417 | E64: PST | F64: Zhenyu Qiao | G64: 网站付款 | H64: 已完成 | I64: USD | J64: 20.25 | K64: -1.2 | L64: 19.05 | M64: =IF(L64>0,L64,0) -> 19.05 | N64: =IF(L64<0,L64,0)*-1 -> 0 | O64: 13X24647AK328224V | P64: 327.91
A65: 45701 | B65: 2025 | C65: 2 | D65: 0.98634259 | E65: PST | F65: 广生 林 | G65: 定期付款 | H65: 已完成 | I65: USD | J65: 0.93 | K65: -0.54 | L65: 0.39 | M65: =IF(L65>0,L65,0) -> 0.39 | N65: =IF(L65<0,L65,0)*-1 -> 0 | O65: 0H290001XG6149442 | P65: 328.3
A66: 45702 | B66: 2025 | C66: 2 | D66: 0.040162037 | E66: PST | F66: 广生 林 | G66: 定期付款 | H66: 已完成 | I66: USD | J66: 3.99 | K66: -0.69 | L66: 3.3 | M66: =IF(L66>0,L66,0) -> 3.3 | N66: =IF(L66<0,L66,0)*-1 -> 0 | O66: 73T8750287591393R | P66: 331.6
A67: 45702 | B67: 2025 | C67: 2 | D67: 0.041493056 | E67: PST | F67: Namecheap, Inc | G67: 快速结账付款 | H67: 已完成 | I67: USD | J67: -11.66 | K67: 0 | L67: -11.66 | M67: =IF(L67>0,L67,0) -> 0 | N67: =IF(L67<0,L67,0)*-1 -> 11.66 | O67: 3K1926827D397541B | P67: 319.94
A68: 45704 | B68: 2025 | C68: 2 | D68: 0.14650463 | E68: PST | F68: Junjie Xiao | G68: 定期付款 | H68: 已完成 | I68: USD | J68: 1.09 | K68: -0.54 | L68: 0.55 | M68: =IF(L68>0,L68,0) -> 0.55 | N68: =IF(L68<0,L68,0)*-1 -> 0 | O68: 24Y40503T0285030A | P68: 320.49
A69: 45705 | B69: 2025 | C69: 2 | D69: 0.85055556 | E69: PST | F69: Tuchman Aridia | G69: 定期付款 | H69: 已完成 | I69: USD | J69: 20.25 | K69: -1.5 | L69: 18.75 | M69: =IF(L69>0,L69,0) -> 18.75 | N69: =IF(L69<0,L69,0)*-1 -> 0 | O69: 5PT170152T050554W | P69: 339.24
A70: 45707 | B70: 2025 | C70: 2 | D70: 0.030601852 | E70: PST | F70: Jugran Sureka | G70: 网站付款 | H70: 已完成 | I70: USD | J70: 115.19 | K70: -6.24 | L70: 108.95 | M70: =IF(L70>0,L70,0) -> 108.95 | N70: =IF(L70<0,L70,0)*-1 -> 0 | O70: 3XP526149C9025608 | P70: 448.19
A71: 45708 | B71: 2025 | C71: 2 | D71: 0.22570602 | E71: PST | F71: 翔 梁 | G71: 网站付款 | H71: 已完成 | I71: USD | J71: 8.39 | K71: -0.91 | L71: 7.48 | M71: =IF(L71>0,L71,0) -> 7.48 | N71: =IF(L71<0,L71,0)*-1 -> 0 | O71: 8BH27129SJ672351V | P71: 455.67
A72: 45708 | B72: 2025 | C72: 2 | D72: 0.42359954 | E72: PST | F72: junwu chen | G72: 定期付款 | H72: 已完成 | I72: USD | J72: 8.4 | K72: -0.78 | L72: 7.62 | M72: =IF(L72>0,L72,0) -> 7.62 | N72: =IF(L72<0,L72,0)*-1 -> 0 | O72: 8SA15316EE6282820 | P72: 463.29
A73: 45709 | B73: 2025 | C73: 2 | D73: 0.14020833 | E73: PST | F73: SHENG CHUANLONG | G73: 定期付款 | H73: 已完成 | I73: USD | J73: 4.99 | K73: -0.74 | L73: 4.25 | M73: =IF(L73>0,L73,0) -> 4.25 | N73: =IF(L73<0,L73,0)*-1 -> 0 | O73: 8BJ206916B618903T | P73: 467.54
A74: 45709 | B74: 2025 | C74: 2 | D74: 0.28217593 | E74: PST | F74: 广生 林 | G74: 网站付款 | H74: 已完成 | I74: USD | J74: 4 | K74: -0.69 | L74: 3.31 | M74: =IF(L74>0,L74,0) -> 3.31 | N74: =IF(L74<0,L74,0)*-1 -> 0 | O74: 8CT65871LH383173E | P74: 470.85
A75: 45709 | B75: 2025 | C75: 2 | D75: 0.36858796 | E75: PST | F75: tof dao | G75: 网站付款 | H75: 已完成 | I75: USD | J75: 8.39 | K75: -0.91 | L75: 7.48 | M75: =IF(L75>0,L75,0) -> 7.48 | N75: =IF(L75<0,L75,0)*-1 -> 0 | O75: 3US37306AT524140B | P75: 478.33
...

Sheet USDT2025
A1: # | B1: 日期 | C1: 年 | D1: 月份 | E1: 对象 | F1: 类型 | G1: 描述 | H1: 收入 | I1: 支出 | J1: 结算否 | K1: 是否对帐 | L1: 结算总额 | M1: 结算日期 | N1: 结算银行 | O1: 备注
A2: 1 | B2: 45607 | C2: =YEAR(B2) -> 2024 | D2: =MONTH(B2) -> 11 | E2: NiiHost | F2: USDT | G2: 销售收入 | H2: 499.2897 | J2: 已结算 | K2: TRUE | L2: =SUM(H2:H15) -> 1452.3151 | M2: 45693 | N2: 水星银行SF | O2: 5笔USDT转换手续费 1.5x5
A3: 2 | B3: 45607 | C3: =YEAR(B3) -> 2024 | D3: =MONTH(B3) -> 11 | E3: NiiHost | F3: USDT | G3: 销售收入 | H3: 100 | J3: 已结算 | K3: TRUE | L3: 1452.3151 | M3: 45693 | N3: 水星银行SF | O3: 5笔USDT转换手续费 1.5x5
A4: 3 | B4: 45618 | C4: =YEAR(B4) -> 2024 | D4: =MONTH(B4) -> 11 | E4: NiiHost | F4: USDT | G4: 销售收入 | H4: 16.203 | J4: 已结算 | K4: TRUE | L4: 1452.3151 | M4: 45693 | N4: 水星银行SF | O4: 5笔USDT转换手续费 1.5x5
A5: 4 | B5: 45623 | C5: =YEAR(B5) -> 2024 | D5: =MONTH(B5) -> 11 | E5: NiiHost | F5: USDT | G5: 销售收入 | H5: 7.9986 | J5: 已结算 | K5: TRUE | L5: 1452.3151 | M5: 45693 | N5: 水星银行SF | O5: 5笔USDT转换手续费 1.5x5
A6: 5 | B6: 45624 | C6: =YEAR(B6) -> 2024 | D6: =MONTH(B6) -> 11 | E6: NiiHost | F6: USDT | G6: 销售收入 | H6: 12.589 | J6: 已结算 | K6: TRUE | L6: 1452.3151 | M6: 45693 | N6: 水星银行SF | O6: 5笔USDT转换手续费 1.5x5
A7: 6 | B7: 45625 | C7: =YEAR(B7) -> 2024 | D7: =MONTH(B7) -> 11 | E7: NiiHost | F7: USDT | G7: 销售收入 | H7: 7.2089 | J7: 已结算 | K7: TRUE | L7: 1452.3151 | M7: 45693 | N7: 水星银行SF | O7: 5笔USDT转换手续费 1.5x5
A8: 7 | B8: 45629 | C8: 2024 | D8: 12 | E8: NiiHost | F8: USDT | G8: 销售收入 | H8: 16.7572 | J8: 已结算 | K8: TRUE | L8: 1452.3151 | M8: 45693 | N8: 水星银行SF | O8: 5笔USDT转换手续费 1.5x5
A9: 8 | B9: 45632 | C9: 2024 | D9: 12 | E9: NiiHost | F9: USDT | G9: 销售收入 | H9: 3.9876 | J9: 已结算 | K9: TRUE | L9: 1452.3151 | M9: 45693 | N9: 水星银行SF | O9: 5笔USDT转换手续费 1.5x5
A10: 9 | B10: 45636 | C10: 2024 | D10: 12 | E10: NiiHost | F10: USDT | G10: 销售收入 | H10: 16.8003 | J10: 已结算 | K10: TRUE | L10: 1452.3151 | M10: 45693 | N10: 水星银行SF | O10: 5笔USDT转换手续费 1.5x5
A11: 10 | B11: 45636 | C11: 2024 | D11: 12 | E11: NiiHost | F11: USDT | G11: 销售收入 | H11: 600 | J11: 已结算 | K11: TRUE | L11: 1452.3151 | M11: 45693 | N11: 水星银行SF | O11: 5笔USDT转换手续费 1.5x5
A12: 11 | B12: 45643 | C12: 2024 | D12: 12 | E12: NiiHost | F12: USDT | G12: 销售收入 | H12: 10.9808 | J12: 已结算 | K12: TRUE | L12: 1452.3151 | M12: 45693 | N12: 水星银行SF | O12: 5笔USDT转换手续费 1.5x5
A13: 12 | B13: 45652 | C13: 2024 | D13: 12 | E13: NiiHost | F13: USDT | G13: 销售收入 | H13: 120 | J13: 已结算 | K13: TRUE | L13: 1452.3151 | M13: 45693 | N13: 水星银行SF | O13: 5笔USDT转换手续费 1.5x5
A14: 13 | B14: 45653 | C14: 2024 | D14: 12 | E14: NiiHost | F14: USDT | G14: 销售收入 | H14: 20.25 | J14: 已结算 | K14: TRUE | L14: 1452.3151 | M14: 45693 | N14: 水星银行SF | O14: 5笔USDT转换手续费 1.5x5
A15: 14 | B15: 45654 | C15: 2024 | D15: 12 | E15: NiiHost | F15: USDT | G15: 销售收入 | H15: 20.25 | J15: 已结算 | K15: TRUE | L15: 1452.3151 | M15: 45693 | N15: 水星银行SF | O15: 5笔USDT转换手续费 1.5x5
A16: 15 | B16: 45598 | C16: 2024 | D16: 11 | E16: AFF | F16: USDT | G16: 业务支出 | I16: 41.06 | K16: TRUE | O16: AF支付给张雨萱
A17: 16 | B17: 45628 | C17: 2024 | D17: 12 | E17: AFF | F17: USDT | G17: 业务支出 | I17: 62.8 | K17: TRUE | O17: AF支付给张雨萱
A18: 17 | B18: 45642 | C18: 2024 | D18: 12 | E18: AFF | F18: USDT | G18: 业务支出 | I18: 36.35 | K18: TRUE | O18: AF支付给优哥
A19: 18 | B19: 45659 | C19: 2025 | D19: 1 | E19: NiiHost | F19: USDT | G19: 销售收入 | H19: 8 | J19: 已结算 | K19: TRUE
A20: 19 | B20: 45663 | C20: 2025 | D20: 1 | E20: NiiHost | F20: USDT | G20: 销售收入 | H20: 2.49 | J20: 已结算 | K20: TRUE
A21: 20 | B21: 45664 | C21: 2025 | D21: 1 | E21: NiiHost | F21: USDT | G21: 销售收入 | H21: 17.7271 | J21: 已结算 | K21: TRUE
A22: 21 | B22: 45667 | C22: 2025 | D22: 1 | E22: Niihost | F22: USDT | G22: 销售收入 | H22: 600 | J22: 已结算 | K22: TRUE
A23: 22 | B23: 45667 | C23: 2025 | D23: 1 | E23: NiiHost | F23: USDT | G23: 销售收入 | H23: 72.0109 | J23: 已结算 | K23: TRUE
A24: 23 | B24: 45668 | C24: 2025 | D24: 1 | E24: NiiHost | F24: USDT | G24: 销售收入 | H24: 2 | J24: 已结算 | K24: TRUE
A25: 24 | B25: 45668 | C25: 2025 | D25: 1 | E25: NiiHost | F25: USDT | G25: 销售收入 | H25: 2 | J25: 已结算 | K25: TRUE
A26: 25 | B26: 45673 | C26: 2025 | D26: 1 | E26: Niihost | F26: USDT | G26: 销售收入 | H26: 6.7847 | J26: 已结算 | K26: TRUE
A27: 26 | B27: 45673 | C27: 2025 | D27: 1 | E27: NiiHost | F27: USDT | G27: 销售收入 | H27: 17.9932 | J27: 已结算 | K27: TRUE
A28: 27 | B28: 45673 | C28: 2025 | D28: 1 | E28: NiiHost | F28: USDT | G28: 销售收入 | H28: 70.0055 | J28: 已结算 | K28: TRUE
A29: 28 | B29: 45681 | C29: 2025 | D29: 1 | E29: NiiHost | F29: USDT | G29: 销售收入 | H29: 5.9712 | J29: 已结算 | K29: TRUE
A30: 29 | B30: 45685 | C30: 2025 | D30: 1 | E30: Niihost | F30: USDT | G30: 销售收入 | H30: 3.9986 | J30: 已结算 | K30: TRUE
A31: 30 | B31: 45688 | C31: 2025 | D31: 1 | E31: NiiHost | F31: USDT | G31: 销售收入 | H31: 18.1939 | J31: 已结算 | K31: TRUE
A32: 31 | B32: 45698 | C32: 2025 | D32: 2 | E32: NiiHost | F32: 银行转帐 | G32: 业务支出 | I32: 1452.3151 | J32: 已结算 | K32: TRUE | L32: 1452.3151 | M32: 45693 | N32: 水星银行SF | O32: 转到水星支付账单，5笔USDT转换手续费 1.5x5
A33: 32 | B33: 45698 | C33: 2025 | D33: 2 | E33: AFF | F33: USDT | G33: 业务支出 | I33: 41.41 | J33: 已结算 | K33: TRUE | O33: AF支付给张雨萱
A34: 33 | B34: 45698 | C34: 2025 | D34: 2 | E34: NiiHost | F34: USDT | G34: 销售收入 | H34: 600 | J34: 已结算 | K34: TRUE | O34: 可达鸭
A35: 34 | B35: 45699 | C35: 2025 | D35: 2 | E35: NiiHost | F35: USDT | G35: 销售收入 | H35: 48.9617 | J35: 已结算 | K35: TRUE
A36: 35 | B36: 45705 | C36: 2025 | D36: 2 | E36: Niihost | F36: USDT | G36: 销售收入 | H36: 70.1517 | K36: TRUE
A37: 36 | B37: 45707 | C37: 2025 | D37: 2 | E37: NiiHost | F37: USDT | G37: 销售收入 | H37: 100 | K37: TRUE
A38: 37 | B38: 45714 | C38: 2025 | D38: 2 | E38: NiiHost | F38: USDT | G38: 销售收入 | H38: 2.9986 | K38: TRUE
A39: 38 | B39: 45718 | C39: 2025 | D39: 3 | E39: NiiHost | F39: USDT | G39: 销售收入 | H39: 59.9821 | K39: TRUE
A40: 39 | B40: 45718 | C40: 2025 | D40: 3 | E40: NiiHost | F40: USDT | G40: 销售收入 | H40: 59.9822 | K40: TRUE
...

Sheet 支付宝
A1: # | B1: 日期 | C1: 年 | D1: 月份 | E1: 对象 | F1: 类型 | G1: 描述 | H1: 收入 | I1: 支出 | J1: 结算否 | K1: 是否对帐 | L1: 结算总额 | M1: 结算日期 | N1: 结算银行 | O1: 备注
A2: 1 | B2: 45753 | C2: =YEAR(B2) -> 2025 | D2: =MONTH(B2) -> 4 | E2: NiiHost | F2: 银行转帐 | G2: 销售收入 | H2: 836 | J2: 已结算 | K2: TRUE | N2: 支付宝 | O2: 老孙
A3: 2 | B3: 45785 | C3: =YEAR(B3) -> 2025 | D3: =MONTH(B3) -> 5 | E3: NiiHost | F3: 银行转帐 | G3: 销售收入 | H3: 300 | J3: 已结算 | K3: TRUE | N3: 支付宝 | O3: 老孙
A4: 3 | B4: 45995 | C4: =YEAR(B4) -> 2025 | D4: 12 | E4: NiiHost | F4: 银行转帐 | G4: 销售收入 | H4: 460 | J4: 已结算 | K4: TRUE | N4: 支付宝 | O4: 老孙,3250

Sheet Wise2025
A1: Y | B1: M | C1: ID | D1: Status | E1: Direction | F1: Created on | G1: Finished on | H1: Source fee amount | I1: Source fee currency | J1: Target fee amount | K1: Target fee currency | L1: Source name | M1: Source amount (after fees) | N1: IN | O1: OUT | P1: Source currency | Q1: Target name | R1: Target amount (after fees) | S1: Target currency | T1: Exchange rate | U1: Reference | V1: Batch | W1: Created by
A2: 2025 | B2: 1 | C2: TRANSFER-1396540848 | D2: COMPLETED | E2: IN | F2: 45688.209 | G2: 45688.209 | H2: 0 | I2: USD | L2: STRIPE | M2: 26.5 | N2: =IF(E2="IN",M2,0) -> 26.5 | O2: =IF(E2="OUT",M2+H2,0) -> 0 | P2: USD | Q2: Stars Flying Inc | R2: 26.5 | S2: USD | T2: 1 | U2: TRANSFER | W2: XIANG JIAO
A3: 2025 | B3: 1 | C3: TRANSFER-1395031004 | D3: COMPLETED | E3: IN | F3: 45687.208 | G3: 45687.208 | H3: 0 | I3: USD | L3: STRIPE | M3: 24.57 | N3: =IF(E3="IN",M3,0) -> 24.57 | O3: =IF(E3="OUT",M3+H3,0) -> 0 | P3: USD | Q3: Stars Flying Inc | R3: 24.57 | S3: USD | T3: 1 | U3: TRANSFER | W3: XIANG JIAO
A4: 2025 | B4: 1 | C4: TRANSFER-1393613702 | D4: COMPLETED | E4: IN | F4: 45686.209 | G4: 45686.209 | H4: 0 | I4: USD | L4: STRIPE | M4: 141.59 | N4: =IF(E4="IN",M4,0) -> 141.59 | O4: =IF(E4="OUT",M4+H4,0) -> 0 | P4: USD | Q4: Stars Flying Inc | R4: 141.59 | S4: USD | T4: 1 | U4: TRANSFER | W4: XIANG JIAO
A5: 2025 | B5: 1 | C5: TRANSFER-1392185108 | D5: COMPLETED | E5: IN | F5: 45685.209 | G5: 45685.21 | H5: 0 | I5: USD | L5: STRIPE | M5: 9.1 | N5: =IF(E5="IN",M5,0) -> 9.1 | O5: =IF(E5="OUT",M5+H5,0) -> 0 | P5: USD | Q5: Stars Flying Inc | R5: 9.1 | S5: USD | T5: 1 | U5: TRANSFER | W5: XIANG JIAO
A6: 2025 | B6: 1 | C6: TRANSFER-1391386775 | D6: COMPLETED | E6: IN | F6: 45684.598 | G6: 45684.599 | H6: 0 | I6: USD | L6: STRIPE | M6: 67.53 | N6: =IF(E6="IN",M6,0) -> 67.53 | O6: =IF(E6="OUT",M6+H6,0) -> 0 | P6: USD | Q6: Stars Flying Inc | R6: 67.53 | S6: USD | T6: 1 | U6: TRANSFER | W6: XIANG JIAO
A7: 2025 | B7: 1 | C7: TRANSFER-1387449294 | D7: COMPLETED | E7: IN | F7: 45681.21 | G7: 45681.21 | H7: 0 | I7: USD | L7: STRIPE | M7: 52.59 | N7: =IF(E7="IN",M7,0) -> 52.59 | O7: =IF(E7="OUT",M7+H7,0) -> 0 | P7: USD | Q7: Stars Flying Inc | R7: 52.59 | S7: USD | T7: 1 | U7: TRANSFER | W7: XIANG JIAO
A8: 2025 | B8: 1 | C8: TRANSFER-1386084889 | D8: COMPLETED | E8: IN | F8: 45680.209 | G8: 45680.209 | H8: 0 | I8: USD | L8: STRIPE | M8: 249.19 | N8: =IF(E8="IN",M8,0) -> 249.19 | O8: =IF(E8="OUT",M8+H8,0) -> 0 | P8: USD | Q8: Stars Flying Inc | R8: 249.19 | S8: USD | T8: 1 | U8: TRANSFER | W8: XIANG JIAO
A9: 2025 | B9: 1 | C9: TRANSFER-1384738483 | D9: COMPLETED | E9: IN | F9: 45679.209 | G9: 45679.209 | H9: 0 | I9: USD | L9: STRIPE | M9: 106.01 | N9: =IF(E9="IN",M9,0) -> 106.01 | O9: =IF(E9="OUT",M9+H9,0) -> 0 | P9: USD | Q9: Stars Flying Inc | R9: 106.01 | S9: USD | T9: 1 | U9: TRANSFER | W9: XIANG JIAO
A10: 2025 | B10: 1 | C10: TRANSFER-1384006635 | D10: COMPLETED | E10: IN | F10: 45678.599 | G10: 45678.599 | H10: 0 | I10: USD | L10: STRIPE | M10: 114.36 | N10: =IF(E10="IN",M10,0) -> 114.36 | O10: =IF(E10="OUT",M10+H10,0) -> 0 | P10: USD | Q10: Stars Flying Inc | R10: 114.36 | S10: USD | T10: 1 | U10: TRANSFER | W10: XIANG JIAO
A11: 2025 | B11: 1 | C11: TRANSFER-1378923686 | D11: COMPLETED | E11: IN | F11: 45674.209 | G11: 45674.209 | H11: 0 | I11: USD | L11: STRIPE | M11: 57.6 | N11: =IF(E11="IN",M11,0) -> 57.6 | O11: =IF(E11="OUT",M11+H11,0) -> 0 | P11: USD | Q11: Stars Flying Inc | R11: 57.6 | S11: USD | T11: 1 | U11: TRANSFER | W11: XIANG JIAO
A12: 2025 | B12: 1 | C12: TRANSFER-1377542037 | D12: COMPLETED | E12: IN | F12: 45673.209 | G12: 45673.21 | H12: 0 | I12: USD | L12: STRIPE | M12: 1.64 | N12: =IF(E12="IN",M12,0) -> 1.64 | O12: =IF(E12="OUT",M12+H12,0) -> 0 | P12: USD | Q12: Stars Flying Inc | R12: 1.64 | S12: USD | T12: 1 | U12: TRANSFER | W12: XIANG JIAO
A13: 2025 | B13: 1 | C13: TRANSFER-1376080546 | D13: COMPLETED | E13: IN | F13: 45672.21 | G13: 45672.21 | H13: 0 | I13: USD | L13: STRIPE | M13: 152.08 | N13: =IF(E13="IN",M13,0) -> 152.08 | O13: =IF(E13="OUT",M13+H13,0) -> 0 | P13: USD | Q13: Stars Flying Inc | R13: 152.08 | S13: USD | T13: 1 | U13: TRANSFER | W13: XIANG JIAO
... A22: 2025 | B22: 1 | C22: TRANSFER-1364922592 | D22: COMPLETED | E22: IN | F22: 45663.601 | G22: 45663.601 | H22: 0 | I22: USD | L22: STRIPE | M22: 119.04 | N22: =IF(E22="IN",M22,0) -> 119.04 | O22: =IF(E22="OUT",M22+H22,0) -> 0 | P22: USD | Q22: Stars Flying Inc | R22: 119.04 | S22: USD | T22: 1 | U22: TRANSFER | W22: XIANG JIAO
A23: 2025 | B23: 1 | C23: TRANSFER-1364198099 | D23: COMPLETED | E23: OUT | F23: 45663.256 | G23: 45663.256 | H23: 0 | I23: USD | L23: Stars Flying Inc | M23: 400 | N23: =IF(E23="IN",M23,0) -> 0 | O23: =IF(E23="OUT",M23+H23,0) -> 400 | P23: USD | Q23: MIN CHEN | R23: 400 | S23: USD | T23: 1 | U23: 579221 | W23: XIANG JIAO
A24: 2025 | B24: 1 | C24: TRANSFER-1360784844 | D24: COMPLETED | E24: IN | F24: 45660.208 | G24: 45660.209 | H24: 0 | I24: USD | L24: STRIPE | M24: 150.43 | N24: =IF(E24="IN",M24,0) -> 150.43 | O24: =IF(E24="OUT",M24+H24,0) -> 0 | P24: USD | Q24: Stars Flying Inc | R24: 150.43 | S24: USD | T24: 1 | U24: TRANSFER | W24: XIANG JIAO
A25: 2025 | B25: 1 | C25: TRANSFER-1359139264 | D25: COMPLETED | E25: OUT | F25: 45659.142 | G25: 45659.608 | H25: 1.13 | I25: USD | L25: Stars Flying Inc | M25: 1395.08 | N25: =IF(E25="IN",M25,0) -> 0 | O25: =IF(E25="OUT",M25+H25,0) -> 1396.21 | P25: USD | Q25: O2 Network Limited | R25: 1395.08 | S25: USD | T25: 1 | U25: 202501 fee | W25: XIANG JIAO
A26: 2025 | B26: 1 | C26: TRANSFER-1359899450 | D26: COMPLETED | E26: IN | F26: 45659.597 | G26: 45659.598 | H26: 0 | I26: USD | L26: STRIPE | M26: 608.31 | N26: =IF(E26="IN",M26,0) -> 608.31 | O26: =IF(E26="OUT",M26+H26,0) -> 0 | P26: USD | Q26: Stars Flying Inc | R26: 608.31 | S26: USD | T26: 1 | U26: TRANSFER | W26: XIANG JIAO
A27: 2025 | B27: 2 | C27: TRANSFER-1431133946 | D27: COMPLETED | E27: OUT | F27: 45714.324 | G27: 45714.608 | H27: 1.13 | I27: USD | L27: Stars Flying Inc | M27: 1782.62 | N27: =IF(E27="IN",M27,0) -> 0 | O27: =IF(E27="OUT",M27+H27,0) -> 1783.75 | P27: USD | Q27: Stars Flying Inc | R27: 1782.62 | S27: USD | T27: 1 | W27: XIANG JIAO
A28: 2025 | B28: 2 | C28: TRANSFER-1430972366 | D28: COMPLETED | E28: IN | F28: 45714.208 | G28: 45714.208 | H28: 0 | I28: USD | L28: STRIPE | M28: 128.57 | N28: =IF(E28="IN",M28,0) -> 128.57 | O28: =IF(E28="OUT",M28+H28,0) -> 0 | P28: USD | Q28: Stars Flying Inc | R28: 128.57 | S28: USD | T28: 1 | U28: TRANSFER | W28: XIANG JIAO
A29: 2025 | B29: 2 | C29: TRANSFER-1429462782 | D29: COMPLETED | E29: IN | F29: 45713.208 | G29: 45713.208 | H29: 0 | I29: USD | L29: STRIPE | M29: 114.18 | N29: =IF(E29="IN",M29,0) -> 114.18 | O29: =IF(E29="OUT",M29+H29,0) -> 0 | P29: USD | Q29: Stars Flying Inc | R29: 114.18 | S29: USD | T29: 1 | U29: TRANSFER | W29: XIANG JIAO
A30: 2025 | B30: 2 | C30: TRANSFER-1428681578 | D30: COMPLETED | E30: IN | F30: 45712.599 | G30: 45712.599 | H30: 0 | I30: USD | L30: STRIPE | M30: 81.91 | N30: =IF(E30="IN",M30,0) -> 81.91 | O30: =IF(E30="OUT",M30+H30,0) -> 0 | P30: USD | Q30: Stars Flying Inc | R30: 81.91 | S30: USD | T30: 1 | U30: TRANSFER | W30: XIANG JIAO
A31: 2025 | B31: 2 | C31: TRANSFER-1424873508 | D31: COMPLETED | E31: IN | F31: 45709.208 | G31: 45709.209 | H31: 0 | I31: USD | L31: STRIPE | M31: 18.36 | N31: =IF(E31="IN",M31,0) -> 18.36 | O31: =IF(E31="OUT",M31+H31,0) -> 0 | P31: USD | Q31: Stars Flying Inc | R31: 18.36 | S31: USD | T31: 1 | U31: TRANSFER | W31: XIANG JIAO
A32: 2025 | B32: 2 | C32: TRANSFER-1423502861 | D32: COMPLETED | E32: IN | F32: 45708.208 | G32: 45708.209 | H32: 0 | I32: USD | L32: STRIPE | M32: 96.13 | N32: =IF(E32="IN",M32,0) -> 96.13 | O32: =IF(E32="OUT",M32+H32,0) -> 0 | P32: USD | Q32: Stars Flying Inc | R32: 96.13 | S32: USD | T32: 1 | U32: TRANSFER | W32: XIANG JIAO
A33: 2025 | B33: 2 | C33: TRANSFER-1422169092 | D33: COMPLETED | E33: IN | F33: 45707.209 | G33: 45707.209 | H33: 0 | I33: USD | L33: STRIPE | M33: 21.08 | N33: =IF(E33="IN",M33,0) -> 21.08 | O33: =IF(E33="OUT",M33+H33,0) -> 0 | P33: USD | Q33: Stars Flying Inc | R33: 21.08 | S33: USD | T33: 1 | U33: TRANSFER | W33: XIANG JIAO
A34: 2025 | B34: 2 | C34: TRANSFER-1421419459 | D34: COMPLETED | E34: IN | F34: 45706.599 | G34: 45706.599 | H34: 0 | I34: USD | L34: STRIPE | M34: 34.34 | N34: =IF(E34="IN",M34,0) -> 34.34 | O34: =IF(E34="OUT",M34+H34,0) -> 0 | P34: USD | Q34: Stars Flying Inc | R34: 34.34 | S34: USD | T34: 1 | U34: TRANSFER | W34: XIANG JIAO
A35: 2025 | B35: 2 | C35: TRANSFER-1416052183 | D35: COMPLETED | E35: IN | F35: 45702.209 | G35: 45702.209 | H35: 0 | I35: USD | L35: STRIPE | M35: 50.5 | N35: =IF(E35="IN",M35,0) -> 50.5 | O35: =IF(E35="OUT",M35+H35,0) -> 0 | P35: USD | Q35: Stars Flying Inc | R35: 50.5 | S35: USD | T35: 1 | U35: TRANSFER | W35: XIANG JIAO
A36: 2025 | B36: 2 | C36: TRANSFER-1414648589 | D36: COMPLETED | E36: IN | F36: 45701.208 | G36: 45701.567 | H36: 0 | I36: USD | L36: STRIPE | M36: 7.15 | N36: =IF(E36="IN",M36,0) -> 7.15 | O36: =IF(E36="OUT",M36+H36,0) -> 0 | P36: USD | Q36: Stars Flying Inc | R36: 7.15 | S36: USD | T36: 1 | U36: TRANSFER | W36: XIANG JIAO
A37: 2025 | B37: 2 | C37: TRANSFER-1413933449 | D37: COMPLETED | E37: IN | F37: 45700.599 | G37: 45700.6 | H37: 0 | I37: USD | L37: PAYPAL | M37: 500 | N37: =IF(E37="IN",M37,0) -> 500 | O37: =IF(E37="OUT",M37+H37,0) -> 0 | P37: USD | Q37: Stars Flying Inc | R37: 500 | S37: USD | T37: 1 | U37: TRANSFER | W37: XIANG JIAO
A38: 2025 | B38: 2 | C38: TRANSFER-1413302209 | D38: COMPLETED | E38: IN | F38: 45700.209 | G38: 45700.21 | H38: 0 | I38: USD | L38: STRIPE | M38: 29.04 | N38: =IF(E38="IN",M38,0) -> 29.04 | O38: =IF(E38="OUT",M38+H38,0) -> 0 | P38: USD | Q38: Stars Flying Inc | R38: 29.04 | S38: USD | T38: 1 | U38: TRANSFER | W38: XIANG JIAO
A39: 2025 | B39: 2 | C39: DIRECT_DEBIT_TRANSACTION-19834950 | D39: COMPLETED | E39: OUT | F39: 45699.594 | G39: 45699.594 | M39: 19.86 | N39: =IF(E39="IN",M39,0) -> 0 | O39: =IF(E39="OUT",M39+H39,0) -> 19.86 | P39: USD | Q39: STRIPE | R39: 19.86 | S39: USD | T39: 1 | U39: 2025-02-10-224954.644_225458_91000016365878 | W39: XIANG JIAO
A40: 2025 | B40: 2 | C40: TRANSFER-1411153430 | D40: COMPLETED | E40: IN | F40: 45698.64 | G40: 45698.64 | H40: 0 | I40: USD | L40: STRIPE | M40: 53.48 | N40: =IF(E40="IN",M40,0) -> 53.48 | O40: =IF(E40="OUT",M40+H40,0) -> 0 | P40: USD | Q40: Stars Flying Inc | R40: 53.48 | S40: USD | T40: 1 | U40: TRANSFER | W40: XIANG JIAO
A41: 2025 | B41: 2 | C41: TRANSFER-1406954157 | D41: COMPLETED | E41: IN | F41: 45695.208 | G41: 45695.208 | H41: 0 | I41: USD | L41: STRIPE | M41: 1.62 | N41: =IF(E41="IN",M41,0) -> 1.62 | O41: =IF(E41="OUT",M41+H41,0) -> 0 | P41: USD | Q41: Stars Flying Inc | R41: 1.62 | S41: USD | T41: 1 | U41: TRANSFER | W41: XIANG JIAO
A42: 2025 | B42: 2 | C42: TRANSFER-1405461084 | D42: COMPLETED | E42: IN | F42: 45694.208 | G42: 45694.209 | H42: 0 | I42: USD | L42: STRIPE | M42: 76.31 | N42: =IF(E42="IN",M42,0) -> 76.31 | O42: =IF(E42="OUT",M42+H42,0) -> 0 | P42: USD | Q42: Stars Flying Inc | R42: 76.31 | S42: USD | T42: 1 | U42: TRANSFER | W42: XIANG JIAO
A43: 2025 | B43: 2 | C43: TRANSFER-1403837711 | D43: COMPLETED | E43: OUT | F43: 45693.106 | G43: 45693.608 | H43: 1.13 | I43: USD | L43: Stars Flying Inc | M43: 2175.03 | N43: =IF(E43="IN",M43,0) -> 0 | O43: =IF(E43="OUT",M43+H43,0) -> 2176.16 | P43: USD | Q43: O2 Network Limited | R43: 2175.03 | S43: USD | T43: 1 | U43: IDC FEE | W43: XIANG JIAO
A44: 2025 | B44: 2 | C44: TRANSFER-1403917632 | D44: COMPLETED | E44: IN | F44: 45693.208 | G44: 45693.208 | H44: 0 | I44: USD | L44: STRIPE | M44: 50.87 | N44: =IF(E44="IN",M44,0) -> 50.87 | O44: =IF(E44="OUT",M44+H44,0) -> 0 | P44: USD | Q44: Stars Flying Inc | R44: 50.87 | S44: USD | T44: 1 | U44: TRANSFER | W44: XIANG JIAO
A45: 2025 | B45: 2 | C45: TRANSFER-1402313872 | D45: COMPLETED | E45: IN | F45: 45692.209 | G45: 45692.209 | H45: 0 | I45: USD | L45: STRIPE | M45: 57.66 | N45: =IF(E45="IN",M45,0) -> 57.66 | O45: =IF(E45="OUT",M45+H45,0) -> 0 | P45: USD | Q45: Stars Flying Inc | R45: 57.66 | S45: USD | T45: 1 | U45: TRANSFER | W45: XIANG JIAO
A46: 2025 | B46: 2 | C46: TRANSFER-1401379633 | D46: COMPLETED | E46: IN | F46: 45691.601 | G46: 45691.601 | H46: 0 | I46: USD | L46: STRIPE | M46: 11.38 | N46: =IF(E46="IN",M46,0) -> 11.38 | O46: =IF(E46="OUT",M46+H46,0) -> 0 | P46: USD | Q46: Stars Flying Inc | R46: 11.38 | S46: USD | T46: 1 | U46: TRANSFER | W46: XIANG JIAO
A47: 2025 | B47: 4 | C47: TRANSFER-1515648131 | D47: COMPLETED | E47: IN | F47: 4/28/2025 13:21 | G47: 4/28/2025 13:21 | H47: 0 | I47: USD | L47: STRIPE | M47: 675.55 | N47: =IF(E47="IN",M47,0) -> 675.55 | O47: =IF(E47="OUT",M47+H47,0) -> 0 | P47: USD | Q47: Stars Flying Inc | R47: 675.55 | S47: USD | T47: 1 | U47: TRANSFER | W47: XIANG JIAO
A48: 2025 | B48: 4 | C48: TRANSFER-1506203092 | D48: COMPLETED | E48: IN | F48: 4/21/2025 13:21 | G48: 4/21/2025 13:21 | H48: 0 | I48: USD | L48: STRIPE | M48: 586.95 | N48: =IF(E48="IN",M48,0) -> 586.95 | O48: =IF(E48="OUT",M48+H48,0) -> 0 | P48: USD | Q48: Stars Flying Inc | R48: 586.95 | S48: USD | T48: 1 | U48: TRANSFER | W48: XIANG JIAO
...

Sheet Payssion
A1: Date Created | B1: M | C1: App Name | D1: Transaction ID | E1: State | F1: pm_id | G1: Total Amount | H1: Paid Amount | I1: Fee Amount | J1: Net Amount | K1: Refund Amount | L1: Currency | M1: Amount Local | N1: Currency Local | O1: Description | P1: Order Id | Q1: Order Extra | R1: Country
A2: 6/15/2025 17:05 | B2: 6 | C2: niihost | D2: Z615071207130212 | E2: completed | F2: alipay_cn | G2: 13.99 | H2: 13.99 | I2: 0.41 | J2: 13.58 | K2: 0 | L2: USD | O2: NiiHost - 账单编号 #69644 | P2: 69644 | R2: SG
A3: 6/15/2025 16:53 | B3: 6 | C3: niihost | D3: Z615064211711944 | E3: completed | F3: alipay_cn | G3: 14.39 | H3: 14.39 | I3: 0.42 | J3: 13.97 | K3: 0 | L3: USD | O3: NiiHost - 账单编号 #69620 | P3: 69620 | R3: US
A4: 6/15/2025 14:04 | B4: 6 | C4: niihost | D4: Z615962801728599 | E4: completed | F4: alipay_cn | G4: 18.39 | H4: 18.39 | I4: 0.54 | J4: 17.85 | K4: 0 | L4: USD | O4: NiiHost - 账单编号 #69608 | P4: 69608 | R4: CN
A5: 6/16/2025 15:54 | B5: 6 | C5: niihost | D5: Z616892591154823 | E5: completed | F5: alipay_cn | G5: 28.79 | H5: 28.79 | I5: 0.84 | J5: 27.95 | K5: 0 | L5: USD | O5: NiiHost - 账单编号 #69860 | P5: 69860 | R5: JP
A6: 6/16/2025 14:30 | B6: 6 | C6: niihost | D6: Z616842030424225 | E6: completed | F6: alipay_cn | G6: 7.99 | H6: 7.99 | I6: 0.24 | J6: 7.75 | K6: 0 | L6: USD | O6: NiiHost - 账单编号 #69848 | P6: 69848 | R6: US
A7: 6/16/2025 14:09 | B7: 6 | C7: niihost | D7: Z616829595702571 | E7: completed | F7: alipay_cn | G7: 56.79 | H7: 56.79 | I7: 1.65 | J7: 55.14 | K7: 0 | L7: USD | O7: NiiHost - Invoice #69836 | P7: 69836 | R7: CN
A8: 6/17/2025 22:57 | B8: 6 | C8: niihost | D8: Z617010750478726 | E8: completed | F8: alipay_cn | G8: 165.59 | H8: 165.59 | I8: 4.81 | J8: 160.78 | K8: 0 | L8: USD | O8: NiiHost - 账单编号 #70196 | P8: 70196 | R8: HK
A9: 6/17/2025 15:45 | B9: 6 | C9: niihost | D9: Z617751219154849 | E9: completed | F9: alipay_cn | G9: 20.25 | H9: 20.25 | I9: 0.59 | J9: 19.66 | K9: 0 | L9: USD | O9: NiiHost - 账单编号 #70172 | P9: 70172 | R9: KR
A10: 6/17/2025 13:45 | B10: 6 | C10: niihost | D10: Z617679177182219 | E10: completed | F10: alipay_cn | G10: 3.19 | H10: 3.19 | I10: 0.1 | J10: 3.09 | K10: 0 | L10: USD | O10: NiiHost - 账单编号 #70148 | P10: 70148 | R10: US
A11: 6/17/2025 4:36 | B11: 6 | C11: niihost | D11: Z617350142280760 | E11: completed | F11: alipay_cn | G11: 5.99 | H11: 5.99 | I11: 0.18 | J11: 5.81 | K11: 0 | L11: USD | O11: NiiHost - 账单编号 #70124 | P11: 70124 | R11: GB
A12: 6/18/2025 19:54 | B12: 6 | C12: niihost | D12: Z618764975709699 | E12: completed | F12: alipay_cn | G12: 4.79 | H12: 4.79 | I12: 0.14 | J12: 4.65 | K12: 0 | L12: USD | O12: NiiHost - 账单编号 #70641 | P12: 70641 | R12: US
A13: 6/18/2025 15:59 | B13: 6 | C13: niihost | D13: Z618623858631229 | E13: completed | F13: alipay_cn | G13: 17.99 | H13: 17.99 | I13: 0.53 | J13: 17.46 | K13: 0 | L13: USD | O13: NiiHost - 账单编号 #70617 | P13: 70617 | R13: GB
... A21: 6/18/2025 6:05 | B21: 6 | C21: niihost | D21: Z618267348844270 | E21: completed | F21: alipay_cn | G21: 14.39 | H21: 14.39 | I21: 0.42 | J21: 13.97 | K21: 0 | L21: USD | O21: NiiHost - 账单编号 #70364 | P21: 70364 | R21: US
A22: 6/18/2025 5:14 | B22: 6 | C22: niihost | D22: R618236418975823 | E22: refunded | F22: alipay_cn | G22: -4.49 | H22: -4.49 | I22: 0.5 | J22: -4.49 | K22: 3.99 | L22: USD | O22: refund Z618217457125554 | P22: 70340 | Q22: Z618217457125554 | R22: HK
A23: 6/18/2025 5:03 | B23: 6 | C23: niihost | D23: Z618230153955985 | E23: completed | F23: alipay_cn | G23: 20.69 | H23: 20.69 | I23: 0.6 | J23: 20.09 | K23: 0 | L23: USD | O23: NiiHost - Invoice #70208 | P23: 70208 | R23: US
A24: 6/18/2025 4:42 | B24: 6 | C24: niihost | D24: Z618217457125554 | E24: completed | F24: alipay_cn | G24: 3.99 | H24: 3.99 | I24: 0.12 | J24: 3.87 | K24: 3.99 | L24: USD | O24: NiiHost - 账单编号 #70340 | P24: 70340 | R24: HK
A25: 6/18/2025 1:03 | B25: 6 | C25: niihost | D25: Z618086342039709 | E25: completed | F25: alipay_cn | G25: 3.99 | H25: 3.99 | I25: 0.12 | J25: 3.87 | K25: 0 | L25: USD | O25: NiiHost - 账单编号 #70328 | P25: 70328 | R25: HK
A26: 6/19/2025 10:21 | B26: 6 | C26: niihost | D26: Z619284810872039 | E26: completed | F26: alipay_cn | G26: 12.99 | H26: 12.99 | I26: 0.38 | J26: 12.61 | K26: 0 | L26: USD | O26: NiiHost - 账单编号 #70965 | P26: 70965 | R26: US
A27: 6/19/2025 4:10 | B27: 6 | C27: niihost | D27: Z619062519137115 | E27: completed | F27: alipay_cn | G27: 20.69 | H27: 20.69 | I27: 0.6 | J27: 20.09 | K27: 0 | L27: USD | O27: NiiHost - 账单编号 #70929 | P27: 70929 | R27: HK
A28: 6/19/2025 3:48 | B28: 6 | C28: niihost | D28: Z619048875093040 | E28: completed | F28: alipay_cn | G28: 3.99 | H28: 3.99 | I28: 0.12 | J28: 3.87 | K28: 0 | L28: USD | O28: NiiHost - 账单编号 #70917 | P28: 70917 | R28: HK
A29: 6/20/2025 10:23 | B29: 6 | C29: niihost | D29: Z620150069759688 | E29: completed | F29: alipay_cn | G29: 1 | H29: 1 | I29: 0.03 | J29: 0.97 | K29: 0 | L29: USD | O29: NiiHost - 账单编号 #71193 | P29: 71193
A30: 6/20/2025 8:39 | B30: 6 | C30: niihost | D30: Z620087707607169 | E30: completed | F30: alipay_cn | G30: 1.98 | H30: 1.98 | I30: 0.06 | J30: 1.92 | K30: 0 | L30: USD | O30: NiiHost - 账单编号 #71181 | P30: 71181 | R30: CN
A31: 6/20/2025 8:37 | B31: 6 | C31: niihost | D31: Z620086401034816 | E31: completed | F31: alipay_cn | G31: 1.98 | H31: 1.98 | I31: 0.06 | J31: 1.92 | K31: 0 | L31: USD | O31: NiiHost - 账单编号 #71169 | P31: 71169 | R31: CN
A32: 6/20/2025 7:51 | B32: 6 | C32: niihost | D32: Z620059179705188 | E32: completed | F32: alipay_cn | G32: 20.69 | H32: 20.69 | I32: 0.6 | J32: 20.09 | K32: 0 | L32: USD | O32: NiiHost - 账单编号 #71145 | P32: 71145 | R32: JP
A33: 6/20/2025 3:08 | B33: 6 | C33: niihost | D33: Z620889083855269 | E33: completed | F33: alipay_cn | G33: 1 | H33: 1 | I33: 0.03 | J33: 0.97 | K33: 0 | L33: USD | O33: NiiHost - 账单编号 #71109 | P33: 71109 | R33: HK
A34: 6/20/2025 2:05 | B34: 6 | C34: niihost | D34: Z620851369204214 | E34: completed | F34: alipay_cn | G34: 2.99 | H34: 2.99 | I34: 0.09 | J34: 2.9 | K34: 0 | L34: USD | O34: NiiHost - Invoice #71097 | P34: 71097 | R34: US
A35: 6/20/2025 1:36 | B35: 6 | C35: niihost | D35: Z620833681875566 | E35: completed | F35: alipay_cn | G35: 24.25 | H35: 24.25 | I35: 0.71 | J35: 23.54 | K35: 0 | L35: USD | O35: NiiHost - 账单编号 #71013 | P35: 71013 | R35: CN
A36: 6/21/2025 20:43 | B36: 6 | C36: niihost | D36: Z621386107729204 | E36: completed | F36: alipay_cn | G36: 2.99 | H36: 2.99 | I36: 0.09 | J36: 2.9 | K36: 0 | L36: USD | O36: NiiHost - Invoice #71337 | P36: 71337 | R36: CN
A37: 6/21/2025 11:24 | B37: 6 | C37: niihost | D37: Z621050937245256 | E37: completed | F37: alipay_cn | G37: 19.99 | H37: 19.99 | I37: 0.58 | J37: 19.41 | K37: 0 | L37: USD | O37: NiiHost - 账单编号 #71325 | P37: 71325 | R37: US
A38: 6/21/2025 9:47 | B38: 6 | C38: niihost | D38: Z621992402937426 | E38: completed | F38: alipay_cn | G38: 6.99 | H38: 6.99 | I38: 0.21 | J38: 6.78 | K38: 0 | L38: USD | O38: NiiHost - 账单编号 #71313 | P38: 71313 | R38: US
A39: 6/21/2025 1:35 | B39: 6 | C39: niihost | D39: Z621697220531691 | E39: completed | F39: alipay_cn | G39: 2.99 | H39: 2.99 | I39: 0.09 | J39: 2.9 | K39: 0 | L39: USD | O39: NiiHost - 账单编号 #68828 | P39: 68828 | R39: CN
A40: 6/22/2025 16:11 | B40: 6 | C40: niihost | D40: Z622087056007122 | E40: completed | F40: alipay_cn | G40: 5.49 | H40: 5.49 | I40: 0.16 | J40: 5.33 | K40: 0 | L40: USD | O40: NiiHost - 账单编号 #71541 | P40: 71541 | R40: HK
A41: 6/23/2025 15:42 | B41: 6 | C41: niihost | D41: Z623933620275707 | E41: completed | F41: alipay_cn | G41: 20.25 | H41: 20.25 | I41: 0.59 | J41: 19.66 | K41: 0 | L41: USD | O41: NiiHost - 账单编号 #71853 | P41: 71853 | R41: JP
... A49: 6/25/2025 12:19 | B49: 6 | C49: niihost | D49: Z625539412297551 | E49: completed | F49: alipay_cn | G49: 2.99 | H49: 2.99 | I49: 0.09 | J49: 2.9 | K49: 0 | L49: USD | O49: NiiHost - 账单编号 #72429 | P49: 72429 | R49: VN
A50: 6/25/2025 3:23 | B50: 6 | C50: niihost | D50: R625218196687513 | E50: refunded | F50: alipay_cn | G50: -20.75 | H50: -20.75 | I50: 0.5 | J50: -20.75 | K50: 20.25 | L50: USD | O50: refund Z624424338785248 | P50: 72273 | Q50: Z624424338785248 | R50: HK
A51: 6/26/2025 12:22 | B51: 6 | C51: niihost | D51: Z626405420217821 | E51: completed | F51: alipay_cn | G51: 20.75 | H51: 20.75 | I51: 0.61 | J51: 20.14 | K51: 0 | L51: USD | O51: NiiHost - 账单编号 #69128 | P51: 69128 | R51: VN
A52: 6/26/2025 11:14 | B52: 6 | C52: niihost | D52: Z626364432193490 | E52: completed | F52: alipay_cn | G52: 587.99 | H52: 587.99 | I52: 17.06 | J52: 570.93 | K52: 0 | L52: USD | O52: NiiHost - 账单编号 #72789 | P52: 72789 | R52: CN
A53: 6/26/2025 4:07 | B53: 6 | C53: niihost | D53: Z626108683096431 | E53: completed | F53: alipay_cn | G53: 2.01 | H53: 2.01 | I53: 0.06 | J53: 1.95 | K53: 0 | L53: USD | O53: NiiHost - 账单编号 #72753 | P53: 72753 | R53: GB
A54: 6/26/2025 1:17 | B54: 6 | C54: niihost | D54: Z626006406496460 | E54: completed | F54: alipay_cn | G54: 2.99 | H54: 2.99 | I54: 0.09 | J54: 2.9 | K54: 0 | L54: USD | O54: NiiHost - 账单编号 #72741 | P54: 72741 | R54: US
...

Sheet TUTU账目
A1: 序号 | B1: 对象 | C1: 详情 | D1: 账户 | E1: 收入 | F1: 收入日期 | G1: 支出 | H1: 支出日期 | I1: 核实 | J1: 经手人 | K1: 备注
A2: 1 | B2: TUTU | C2: 快车道服务费INV-001874 | D2: Peter | E2: 364.68 | F2: 45468 | G2: 364.68 | H2: 45468 | I2: 已核查 | J2: Thuny
A3: 2 | B3: TUTU | C3: 快车道服务费INV-001891 | D3: Peter | E3: 414.58 | F3: 45474 | G3: 414.58 | H3: 45474 | I3: 已核查 | J3: Thuny
A4: 3 | B4: TUTU | C4: 快车道服务费INV-002005 | D4: Peter | E4: 346.28 | F4: 45504 | G4: 346.28 | H4: 45504 | I4: 已核查 | J4: Thuny
A5: 4 | B5: TUTU | C5: 快车道服务费INV-002135 | D5: Peter | E5: 441.28 | F5: 45535 | G5: 441.28 | H5: 45535 | I5: 已核查 | J5: Thuny
A6: 5 | B6: TUTU | C6: 快车道服务费INV-002275 | D6: Peter | E6: 364.68 | F6: 45536 | G6: 364.68 | H6: 45536 | I6: 已核查 | J6: Thuny
A7: 6 | B7: TUTU | C7: 快车道服务费INV-002435 | D7: Peter | E7: 404.58 | F7: 45596 | G7: 404.58 | H7: 45596 | I7: 已核查 | J7: Thuny
A8: 7 | B8: TUTU | C8: 快车道服务费INV-002603 | D8: Peter | G8: 402.68 | H8: 45626
A9: 8 | B9: TUTU | C9: 快车道服务费INV-002759 | D9: Peter | G9: 409.14 | H9: 45657
A10: 9 | B10: TUTU | C10: 快车道服务费INV-002927 | D10: Peter | G10: 411.8 | H10: 45682
A11: 10 | B11: TUTU | C11: 快车道服务费INV-003095 | D11: Peter | G11: 409.9 | H11: 45716
A12: 11 | B12: TUTU | C12: 快车道服务费INV-003276 | D12: Peter | G12: 401.4 | H12: 45747
A13: 12 | B13: TUTU | C13: 快车道服务费INV-003479 | D13: Peter | G13: 400.12 | H13: 45777
A14: 13 | B14: TUTU | C14: 快车道服务费INV-003674 | D14: Peter | G14: $395.10 | H14: 45811
A15: 14 | B15: TUTU | C15: 快车道服务费INV-003861 | D15: Peter | G15: 374.696 | H15: 45843
A16: 15 | B16: TUTU | C16: 快车道服务费INV-004066 | D16: Peter | G16: 374.76 | H16: 45873
A17: 16 | B17: TUTU | C17: 快车道服务费INV-004278 | D17: Peter | G17: 374.758 | H17: 45907
A18: 17 | B18: TUTU | C18: 快车道服务费INV-004512 | D18: Peter | G18: 374.758 | H18: 45939
A19: 18 | B19: TUTU | C19: 快车道服务费INV-004765 | D19: Peter | G19: 374.787 | H19: 45964
A20: 19 | B20: TUTU | C20: 快车道服务费INV-004988 | D20: Peter | G20: 374.988 | H20: 45992
A21: 20 | B21: TUTU | C21: KURUN 18684，18685 | D21: Peter | G21: 280 | H21: 46003
A22: 21 | B22: TUTU | C22: 快车道服务费INV-005233 | D22: Peter | G22: 373.117 | H22: 46022
A26: 合计 | E26: =SUM(E2:E17) -> 2336.08 | G26: =SUM(G2:G25) -> 7672.984

Sheet 供应商账单
A1: 序号 | B1: 商户 | C1: 账单号 | D1: Year | E1: M | F1: Due Date | G1: Balance Due | H1: power-T | I1: power-N | J1: IPV4-T | K1: IPV4-N | L1: BW | M1: BW-T | N1: BWH-N | O1: 罚金及其它 | P1: SUM | Q1: TuTu | R1: NiiHost | S1: 支付方式 | T1: 支付日期 | U1: 支付情况
A2: 1 | B2: KCD-HK | C2: INV-001874 | D2: 2024 | E2: 6 | F2: 45468 | G2: 631.98 | H2: 314.28 | I2: 164.9 | J2: 50.4 | K2: 102.4 | L2: 0 | M2: 0 | N2: 0 | O2: 0 | P2: =SUM(H2:L2,O2) -> 631.98 | Q2: =SUM(H2,J2,M2) -> 364.68 | R2: =SUM(I2,K2,N2,O2) -> 267.3 | S2: 水星 | U2: 已支付
A3: 2 | B3: KCD-HK | C3: INV-001891 | D3: 2024 | E3: 7 | F3: 45474 | G3: 948.86 | H3: 314.28 | I3: 329.8 | J3: 50.4 | K3: 192 | L3: 62.38 | M3: 49.9 | N3: 12.48 | O3: 0 | P3: =SUM(H3:L3,O3) -> 948.86 | Q3: =SUM(H3,J3,M3) -> 414.58 | R3: =SUM(I3,K3,N3,O3) -> 534.28 | S3: 水星 | U3: 已支付
A4: 3 | B4: KCD-HK | C4: INV-002005 | D4: 2024 | E4: 7 | F4: 45504 | G4: 868.08 | H4: 314.28 | I4: 329.8 | J4: 32 | K4: 192 | L4: 0 | M4: 0 | O4: 0 | P4: =SUM(H4:L4,O4) -> 868.08 | Q4: =SUM(H4,J4,M4) -> 346.28 | R4: =SUM(I4,K4,N4,O4) -> 521.8 | S4: 水星 | U4: 已支付
A5: 4 | B5: KCD-HK | C5: INV-002135 | D5: 2024 | E5: 8 | F5: 45535 | G5: 1269.46 | H5: 314.28 | I5: 329.8 | J5: 50.4 | K5: 192 | L5: 382.98 | M5: 76.6 | N5: 306.38 | O5: 2 | P5: =SUM(H5:L5,O5) -> 1271.46 | Q5: =SUM(H5,J5,M5) -> 441.28 | R5: =SUM(I5,K5,N5,O5) -> 830.18 | S5: 水星 | U5: 已支付
A6: 5 | B6: KCD-HK | C6: INV-002275 | D6: 2024 | E6: 9 | F6: 45536 | G6: 886.48 | H6: 314.28 | I6: 329.8 | J6: 50.4 | K6: 192 | L6: 0 | M6: 0 | N6: 0 | O6: 0 | P6: =SUM(H6:L6,O6) -> 886.48 | Q6: =SUM(H6,J6,M6) -> 364.68 | R6: =SUM(I6,K6,N6,O6) -> 521.8 | S6: 水星 | U6: 已支付
A7: 6 | B7: PQ | C7: 73341 | D7: 2024 | E7: 9 | F7: 45547 | G7: 210 | H7: 0 | I7: 210 | J7: 0 | K7: 0 | L7: 0 | M7: 0 | N7: 0 | O7: 0 | P7: =SUM(H7:L7,O7) -> 210 | Q7: =SUM(H7,J7,M7) -> 0 | R7: =SUM(I7,K7,N7,O7) -> 210 | S7: 水星 | U7: 已支付
A8: 7 | B8: KCD-HK | C8: INV-002435 | D8: 2024 | E8: 10 | F8: 45596 | G8: 1285.48 | H8: 314.28 | I8: 329.8 | J8: 50.4 | K8: 192 | L8: 399 | M8: =IF(B8="KCD-HK",L8*0.1,0) -> 39.9 | N8: =IF(B8="KCD-HK",L8*0.9,L8) -> 359.1 | O8: 0 | P8: =SUM(H8:L8,O8) -> 1285.48 | Q8: =SUM(H8,J8,M8) -> 404.58 | R8: =SUM(I8,K8,N8,O8) -> 880.9 | S8: 水星 | U8: 已支付
A9: 8 | B9: PQ | C9: 75927 | D9: 2024 | E9: 10 | F9: 45596 | G9: 210 | H9: 0 | I9: 210 | J9: 0 | K9: 0 | L9: 0 | M9: =IF(B9="KCD-HK",L9*0.1,0) -> 0 | N9: =IF(B9="KCD-HK",L9*0.9,L9) -> 0 | O9: 0 | P9: =SUM(H9:L9,O9) -> 210 | Q9: =SUM(H9,J9,M9) -> 0 | R9: =SUM(I9,K9,N9,O9) -> 210 | S9: 水星 | U9: 已支付
A10: 9 | B10: PQ | C10: 75928 | D10: 2024 | E10: 11 | F10: 45621 | G10: 250 | H10: 0 | I10: 250 | J10: 0 | K10: 0 | L10: 0 | M10: =IF(B10="KCD-HK",L10*0.1,0) -> 0 | N10: =IF(B10="KCD-HK",L10*0.9,L10) -> 0 | O10: 0 | P10: =SUM(H10:L10,O10) -> 250 | Q10: =SUM(H10,J10,M10) -> 0 | R10: =SUM(I10,K10,N10,O10) -> 250 | S10: 水星 | U10: 已支付
A11: 10 | B11: KCD-HK | C11: INV-002603 | D11: 2024 | E11: 11 | F11: 45626 | G11: 1266.48 | H11: 314.28 | I11: 329.8 | J11: 50.4 | K11: 192 | L11: 380 | M11: =IF(B11="KCD-HK",L11*0.1,0) -> 38 | N11: =IF(B11="KCD-HK",L11*0.9,L11) -> 342 | O11: 20 | P11: =SUM(H11:L11,O11) -> 1286.48 | Q11: =SUM(H11,J11,M11) -> 402.68 | R11: =SUM(I11,K11,N11,O11) -> 883.8 | S11: 水星 | U11: 已支付
A12: 11 | B12: PQ | C12: 77921 | D12: 2024 | E12: 11 | F12: 45624 | G12: 206.49 | H12: 0 | I12: 206.49 | J12: 0 | K12: 0 | L12: 0 | M12: =IF(B12="KCD-HK",L12*0.1,0) -> 0 | N12: =IF(B12="KCD-HK",L12*0.9,L12) -> 0 | O12: 0 | P12: =SUM(H12:L12,O12) -> 206.49 | Q12: =SUM(H12,J12,M12) -> 0 | R12: =SUM(I12,K12,N12,O12) -> 206.49 | S12: WISE | U12: 通过WISE已支付
A13: 12 | B13: KCD-HK | C13: INV-002759 | D13: 2024 | E13: 12 | F13: 45657 | G13: 1395.08 | H13: 314.28 | I13: 329.8 | J13: 50.4 | K13: 256 | L13: 444.6 | M13: =IF(B13="KCD-HK",L13*0.1,0) -> 44.46 | N13: =IF(B13="KCD-HK",L13*0.9,L13) -> 400.14 | O13: 0 | P13: =SUM(H13:L13,O13) -> 1395.08 | Q13: =SUM(H13,J13,M13) -> 409.14 | R13: =SUM(I13,K13,N13,O13) -> 985.94 | S13: WISE | U13: 通过WISE已支付
